Workbook

Sheet Lighting Trials
A1: light_percent | B1: trial | C1: scene | D1: x_m | E1: y_m | F1: detection | G1: confidence | H1: pixel_u | I1: pixel_v | J1: depth_surface_m | K1: depth_center_m | L1: estimated_ground_m | M1: estimated_forward_m | N1: estimated_lateral_m | O1: ground_truth_m | P1: error_m | Q1: error_pct
A2: 100 | B2: 1 | C2: light_longitudinal | D2: 1 | E2: 0
A3: 100 | B3: 2 | C3: light_longitudinal | D3: 1.2632 | E3: 0 | F3: bottle | G3: 0.87 | H3: 640 | I3: 395 | J3: 0.993 | K3: 1.068 | L3: 1.001 | O3: 1 | P3: 0.001 | Q3: 0.1
A4: 100 | B4: 3 | C4: light_longitudinal | D4: 1.5263 | E4: 0 | F4: bottle | G4: 0.9 | H4: 640 | I4: 341 | J4: 1.242 | K4: 1.317 | L4: 1.247 | M4: 1.247 | N4: 0 | O4: 1 | P4: 0.247 | Q4: 24.7
A5: 100 | B5: 4 | C5: light_longitudinal | D5: 1.7895 | E5: 0 | F5: bottle | G5: 0.88 | H5: 639 | I5: 278 | J5: 1.738 | K5: 1.813 | L5: 1.776 | M5: 1.776 | N5: 0.003 | O5: 1.79 | P5: -0.013 | Q5: -0.7
A6: 100 | B6: 5 | C6: light_longitudinal | D6: 2.0526 | E6: 0 | F6: bottle | G6: 0.88 | H6: 639 | I6: 278 | J6: 1.738 | K6: 1.813 | L6: 1.776 | M6: 1.776 | N6: 0.003 | O6: 1.79 | P6: -0.013 | Q6: -0.7
A7: 100 | B7: 6 | C7: light_longitudinal | D7: 2.3158 | E7: 0 | F7: bottle | G7: 0.86 | H7: 639 | I7: 257 | J7: 1.984 | K7: 2.059 | L7: 2.04 | M7: 2.04 | N7: 0.003 | O7: 1.79 | P7: 0.251 | Q7: 14
A8: 100 | B8: 7 | C8: light_longitudinal | D8: 2.5789 | E8: 0 | F8: bottle | G8: 0.31 | H8: 640 | I8: 241 | J8: 2.232 | K8: 2.307 | L8: 2.304 | M8: 2.304 | N8: 0 | O8: 2.316 | P8: -0.012 | Q8: -0.5
A9: 100 | B9: 8 | C9: light_longitudinal | D9: 2.8421 | E9: 0
A10: 100 | B10: 9 | C10: light_longitudinal | D10: 3.1053 | E10: 0 | F10: bottle | G10: 0.63 | H10: 640 | I10: 218 | J10: 2.726 | K10: 2.801 | L10: 2.832 | M10: 2.832 | N10: 0 | O10: 2.842 | P10: -0.01 | Q10: -0.4
A11: 100 | B11: 10 | C11: light_longitudinal | D11: 3.3684 | E11: 0 | F11: bottle | G11: 0.19 | H11: 640 | I11: 209 | J11: 2.973 | K11: 3.048 | L11: 3.095 | M11: 3.095 | N11: 0 | O11: 3.105 | P11: -0.01 | Q11: -0.3
A12: 100 | B12: 11 | C12: light_longitudinal | D12: 3.6316 | E12: 0
A13: 100 | B13: 12 | C13: light_longitudinal | D13: 3.8947 | E13: 0 | F13: bottle | G13: 0.73 | H13: 640 | I13: 194 | J13: 3.465 | K13: 3.54 | L13: 3.622 | M13: 3.622 | N13: 0 | O13: 3.632 | P13: -0.009 | Q13: -0.3
A14: 100 | B14: 13 | C14: light_longitudinal | D14: 4.1579 | E14: 0 | F14: bottle | G14: 0.76 | H14: 641 | I14: 185 | J14: 3.962 | K14: 4.037 | L14: 4.15 | M14: 4.15 | N14: -0.006 | O14: 4.158 | P14: -0.008 | Q14: -0.2
A15: 100 | B15: 14 | C15: light_longitudinal | D15: 4.4211 | E15: 0
A16: 100 | B16: 15 | C16: light_longitudinal | D16: 4.6842 | E16: 0 | F16: bottle | G16: 0.65 | H16: 640 | I16: 180 | J16: 4.207 | K16: 4.282 | L16: 4.413 | M16: 4.413 | N16: 0 | O16: 4.684 | P16: -0.272 | Q16: -5.8
A17: 100 | B17: 16 | C17: light_longitudinal | D17: 4.9474 | E17: 0 | F17: bottle | G17: 0.6 | H17: 640 | I17: 174 | J17: 4.704 | K17: 4.779 | L17: 4.939 | M17: 4.939 | N17: 0 | O17: 4.947 | P17: -0.008 | Q17: -0.2
A18: 100 | B18: 17 | C18: light_longitudinal | D18: 5.2105 | E18: 0 | F18: bottle | G18: 0.6 | H18: 640 | I18: 174 | J18: 4.704 | K18: 4.779 | L18: 4.939 | M18: 4.939 | N18: 0 | O18: 4.947 | P18: -0.008 | Q18: -0.2
A19: 100 | B19: 18 | C19: light_longitudinal | D19: 5.4737 | E19: 0 | F19: bottle | G19: 0.59 | H19: 640 | I19: 170 | J19: 4.949 | K19: 5.024 | L19: 5.203 | M19: 5.203 | N19: 0 | O19: 5.211 | P19: -0.008 | Q19: -0.2
A20: 100 | B20: 19 | C20: light_longitudinal | D20: 5.7368 | E20: 0 | F20: bottle | G20: 0.19 | H20: 639 | I20: 167 | J20: 5.195 | K20: 5.27 | L20: 5.466 | M20: 5.466 | N20: 0.008 | O20: 5.474 | P20: -0.008 | Q20: -0.1
A21: 100 | B21: 20 | C21: light_longitudinal | D21: 6 | E21: 0
A22: 100 | B22: 21 | C22: light_lateral | D22: 3 | E22: -2.75
A23: 100 | B23: 22 | C23: light_lateral | D23: 3 | E23: -2.4605
A24: 100 | B24: 23 | C24: light_lateral | D24: 3 | E24: -2.1711 | F24: bottle | G24: 0.75 | H24: 1199 | I24: 211 | J24: 2.898 | K24: 2.973 | L24: 3.894 | M24: 3.016 | N24: -2.464 | O24: 3.88 | P24: 0.014 | Q24: 0.4
A25: 100 | B25: 24 | C25: light_lateral | D25: 3 | E25: -1.8816 | F25: bottle | G25: 0.75 | H25: 1133 | I25: 211 | J25: 2.894 | K25: 2.969 | L25: 3.713 | M25: 3.012 | N25: -2.17 | O25: 3.703 | P25: 0.009 | Q25: 0.3
A26: 100 | B26: 25 | C26: light_lateral | D26: 3 | E26: -1.5921 | F26: bottle | G26: 0.77 | H26: 1066 | I26: 212 | J26: 4.529 | K26: 4.604 | L26: 5.5 | M26: 4.668 | N26: -2.908 | O26: 3.396 | P26: 2.103 | Q26: 61.9
A27: 100 | B27: 26 | C27: light_lateral | D27: 3 | E27: -1.3026
A28: 100 | B28: 27 | C28: light_lateral | D28: 3 | E28: -1.0132 | F28: bottle | G28: 0.84 | H28: 933 | I28: 212 | J28: 2.889 | K28: 2.964 | L28: 3.27 | M28: 3.005 | N28: -1.288 | O28: 3.271 | P28: -0.001 | Q28: 0
A29: 100 | B29: 28 | C29: light_lateral | D29: 3 | E29: -0.7237
A30: 100 | B30: 29 | C30: light_lateral | D30: 3 | E30: -0.4342
A31: 100 | B31: 30 | C31: light_lateral | D31: 3 | E31: -0.1447
A32: 100 | B32: 31 | C32: light_lateral | D32: 3 | E32: 0.1447 | F32: bottle | G32: 0.84 | H32: 739 | I32: 212 | J32: 2.875 | K32: 2.95 | L32: 3.022 | M32: 2.991 | N32: -0.433 | O32: 3.003 | P32: 0.018 | Q32: 0.6
A33: 100 | B33: 32 | C33: light_lateral | D33: 3 | E33: 0.4342
A34: 100 | B34: 33 | C34: light_lateral | D34: 3 | E34: 0.7237
A35: 100 | B35: 34 | C35: light_lateral | D35: 3 | E35: 1.0132 | F35: bottle | G35: 0.83 | H35: 476 | I35: 212 | J35: 2.878 | K35: 2.953 | L35: 3.079 | M35: 2.994 | N35: 0.718 | O35: 3.166 | P35: -0.087 | Q35: -2.8
A36: 100 | B36: 35 | C36: light_lateral | D36: 3 | E36: 1.3026 | F36: bottle | G36: 0.78 | H36: 410 | I36: 212 | J36: 2.881 | K36: 2.956 | L36: 3.162 | M36: 2.997 | N36: 1.008 | O36: 3.166 | P36: -0.004 | Q36: -0.1
A37: 100 | B37: 36 | C37: light_lateral | D37: 3 | E37: 1.5921 | F37: bottle | G37: 0.83 | H37: 344 | I37: 212 | J37: 2.884 | K37: 2.959 | L37: 3.27 | M37: 3.001 | N37: 1.299 | O37: 3.396 | P37: -0.127 | Q37: -3.7
A38: 100 | B38: 37 | C38: light_lateral | D38: 3 | E38: 1.8816
A39: 100 | B39: 38 | C39: light_lateral | D39: 3 | E39: 2.1711 | F39: bottle | G39: 0.81 | H39: 211 | I39: 211 | J39: 2.888 | K39: 2.963 | L39: 3.548 | M39: 3.006 | N39: 1.885 | O39: 3.703 | P39: -0.155 | Q39: -4.2
A40: 100 | B40: 39 | C40: light_lateral | D40: 3 | E40: 2.4605 | F40: bottle | G40: 0.76 | H40: 145 | I40: 211 | J40: 2.892 | K40: 2.967 | L40: 3.715 | M40: 3.01 | N40: 2.178 | O40: 3.88 | P40: -0.165 | Q40: -4.3
...

Sheet Baseline Trials
A1: trial | B1: scene | C1: x_m | D1: y_m | E1: detection | F1: confidence | G1: pixel_u | H1: pixel_v | I1: depth_surface_m | J1: depth_center_m | K1: estimated_ground_m | L1: estimated_forward_m | M1: estimated_lateral_m | N1: ground_truth_m | O1: error_m | P1: error_pct
A2: 1 | B2: longitudinal_extreme | C2: 1 | D2: 0
A3: 2 | B3: longitudinal_extreme | C3: 1.0505 | D3: 0 | E3: bottle | F3: 0.81 | G3: 640 | H3: 395 | I3: 0.993 | J3: 1.068 | K3: 0.982 | L3: 0.982 | M3: 0 | N3: 1 | O3: -0.018 | P3: -1.8
A4: 3 | B4: longitudinal_extreme | C4: 1.101 | D4: 0 | E4: bottle | F4: 0.88 | G4: 640 | H4: 384 | I4: 1.041 | J4: 1.116 | K4: 1.033 | L4: 1.033 | M4: 0 | N4: 1 | O4: 0.033 | P4: 3.3
A5: 4 | B5: longitudinal_extreme | C5: 1.1515 | D5: 0 | E5: bottle | F5: 0.88 | G5: 640 | H5: 372 | I5: 1.089 | J5: 1.164 | K5: 1.084 | L5: 1.084 | M5: 0 | N5: 1.101 | O5: -0.017 | P5: -1.5
A6: 5 | B6: longitudinal_extreme | C6: 1.202 | D6: 0 | E6: bottle | F6: 0.88 | G6: 640 | H6: 351 | I6: 1.184 | J6: 1.259 | K6: 1.186 | L6: 1.186 | M6: 0 | N6: 1.202 | O6: -0.016 | P6: -1.3
A7: 6 | B7: longitudinal_extreme | C7: 1.2525 | D7: 0 | E7: bottle | F7: 0.88 | G7: 640 | H7: 351 | I7: 1.184 | J7: 1.259 | K7: 1.186 | L7: 1.186 | M7: 0 | N7: 1.253 | O7: -0.067 | P7: -5.3
A8: 7 | B8: longitudinal_extreme | C8: 1.303 | D8: 0 | E8: bottle | F8: 0.89 | G8: 640 | H8: 335 | I8: 1.28 | J8: 1.355 | K8: 1.288 | L8: 1.288 | M8: 0 | N8: 1.303 | O8: -0.015 | P8: -1.2
A9: 8 | B9: longitudinal_extreme | C9: 1.3535 | D9: 0 | E9: bottle | F9: 0.88 | G9: 640 | H9: 326 | I9: 1.326 | J9: 1.401 | K9: 1.338 | L9: 1.338 | M9: 0 | N9: 1.354 | O9: -0.015 | P9: -1.1
A10: 9 | B10: longitudinal_extreme | C10: 1.404 | D10: 0 | E10: bottle | F10: 0.8 | G10: 640 | H10: 320 | I10: 1.375 | J10: 1.45 | K10: 1.389 | L10: 1.389 | M10: 0 | N10: 1.404 | O10: -0.015 | P10: -1.1
A11: 10 | B11: longitudinal_extreme | C11: 1.4545 | D11: 0 | E11: bottle | F11: 0.8 | G11: 640 | H11: 320 | I11: 1.375 | J11: 1.45 | K11: 1.389 | L11: 1.389 | M11: 0 | N11: 1.404 | O11: -0.015 | P11: -1.1
A12: 11 | B12: longitudinal_extreme | C12: 1.5051 | D12: 0
A13: 12 | B13: longitudinal_extreme | C13: 1.5556 | D13: 0 | E13: bottle | F13: 0.87 | G13: 640 | H13: 301 | I13: 1.517 | J13: 1.592 | K13: 1.542 | L13: 1.542 | M13: 0 | N13: 1.556 | O13: -0.014 | P13: -0.9
A14: 13 | B14: longitudinal_extreme | C14: 1.6061 | D14: 0 | E14: bottle | F14: 0.87 | G14: 640 | H14: 296 | I14: 1.565 | J14: 1.64 | K14: 1.592 | L14: 1.592 | M14: 0 | N14: 1.556 | O14: 0.037 | P14: 2.4
A15: 14 | B15: longitudinal_extreme | C15: 1.6566 | D15: 0 | E15: bottle | F15: 0.87 | G15: 640 | H15: 296 | I15: 1.565 | J15: 1.64 | K15: 1.592 | L15: 1.592 | M15: 0 | N15: 1.657 | O15: -0.064 | P15: -3.9
A16: 15 | B16: longitudinal_extreme | C16: 1.7071 | D16: 0 | E16: bottle | F16: 0.88 | G16: 639 | H16: 290 | I16: 1.612 | J16: 1.687 | K16: 1.643 | L16: 1.643 | M16: 0.003 | N16: 1.707 | O16: -0.064 | P16: -3.8
A17: 16 | B17: longitudinal_extreme | C17: 1.7576 | D17: 0
A18: 17 | B18: longitudinal_extreme | C18: 1.8081 | D18: 0 | E18: bottle | F18: 0.87 | G18: 639 | H18: 280 | I18: 1.707 | J18: 1.782 | K18: 1.744 | L18: 1.744 | M18: 0.003 | N18: 1.758 | O18: -0.013 | P18: -0.8
A19: 18 | B19: longitudinal_extreme | C19: 1.8586 | D19: 0 | E19: bottle | F19: 0.83 | G19: 640 | H19: 276 | I19: 1.755 | J19: 1.83 | K19: 1.795 | L19: 1.795 | M19: 0 | N19: 1.808 | O19: -0.013 | P19: -0.7
A20: 19 | B20: longitudinal_extreme | C20: 1.9091 | D20: 0
A21: 20 | B21: longitudinal_extreme | C21: 1.9596 | D21: 0 | E21: bottle | F21: 0.84 | G21: 639 | H21: 264 | I21: 1.897 | J21: 1.972 | K21: 1.947 | L21: 1.947 | M21: 0.003 | N21: 1.96 | O21: -0.013 | P21: -0.6
A22: 21 | B22: longitudinal_extreme | C22: 2.0101 | D22: 0 | E22: bottle | F22: 0.84 | G22: 639 | H22: 264 | I22: 1.897 | J22: 1.972 | K22: 1.947 | L22: 1.947 | M22: 0.003 | N22: 1.96 | O22: -0.013 | P22: -0.6
A23: 22 | B23: longitudinal_extreme | C23: 2.0606 | D23: 0 | E23: bottle | F23: 0.82 | G23: 639 | H23: 259 | I23: 1.944 | J23: 2.019 | K23: 1.998 | L23: 1.998 | M23: 0.003 | N23: 2.01 | O23: -0.012 | P23: -0.6
A24: 23 | B24: longitudinal_extreme | C24: 2.1111 | D24: 0
A25: 24 | B25: longitudinal_extreme | C25: 2.1616 | D25: 0 | E25: bottle | F25: 0.87 | G25: 639 | H25: 254 | I25: 2.091 | J25: 2.166 | K25: 2.15 | L25: 2.15 | M25: 0.003 | N25: 2.162 | O25: -0.012 | P25: -0.6
A26: 25 | B26: longitudinal_extreme | C26: 2.2121 | D26: 0 | E26: bottle | F26: 0.8 | G26: 639 | H26: 247 | I26: 2.134 | J26: 2.209 | K26: 2.2 | L26: 2.2 | M26: 0.003 | N26: 2.212 | O26: -0.012 | P26: -0.5
A27: 26 | B27: longitudinal_extreme | C27: 2.2626 | D27: 0 | E27: bottle | F27: 0.8 | G27: 639 | H27: 247 | I27: 2.134 | J27: 2.209 | K27: 2.2 | L27: 2.2 | M27: 0.003 | N27: 2.263 | O27: -0.062 | P27: -2.8
A28: 27 | B28: longitudinal_extreme | C28: 2.3131 | D28: 0 | E28: bottle | F28: 0.74 | G28: 639 | H28: 244 | I28: 2.182 | J28: 2.257 | K28: 2.251 | L28: 2.251 | M28: 0.003 | N28: 2.263 | O28: -0.012 | P28: -0.5
A29: 28 | B29: longitudinal_extreme | C29: 2.3636 | D29: 0 | E29: bottle | F29: 0.45 | G29: 639 | H29: 239 | I29: 2.277 | J29: 2.352 | K29: 2.352 | L29: 2.352 | M29: 0.003 | N29: 2.364 | O29: -0.011 | P29: -0.5
A30: 29 | B30: longitudinal_extreme | C30: 2.4141 | D30: 0 | E30: bottle | F30: 0.41 | G30: 639 | H30: 236 | I30: 2.324 | J30: 2.399 | K30: 2.403 | L30: 2.403 | M30: 0.004 | N30: 2.414 | O30: -0.011 | P30: -0.5
A31: 30 | B31: longitudinal_extreme | C31: 2.4646 | D31: 0 | E31: bottle | F31: 0.41 | G31: 639 | H31: 236 | I31: 2.324 | J31: 2.399 | K31: 2.403 | L31: 2.403 | M31: 0.004 | N31: 2.465 | O31: -0.062 | P31: -2.5
A32: 31 | B32: longitudinal_extreme | C32: 2.5152 | D32: 0
A33: 32 | B33: longitudinal_extreme | C33: 2.5657 | D33: 0 | E33: bottle | F33: 0.77 | G33: 639 | H33: 228 | I33: 2.465 | J33: 2.54 | K33: 2.555 | L33: 2.555 | M33: 0.004 | N33: 2.566 | O33: -0.011 | P33: -0.4
A34: 33 | B34: longitudinal_extreme | C34: 2.6162 | D34: 0 | E34: bottle | F34: 0.73 | G34: 640 | H34: 226 | I34: 2.513 | J34: 2.588 | K34: 2.605 | L34: 2.605 | M34: 0 | N34: 2.616 | O34: -0.011 | P34: -0.4
A35: 34 | B35: longitudinal_extreme | C35: 2.6667 | D35: 0 | E35: bottle | F35: 0.73 | G35: 640 | H35: 226 | I35: 2.513 | J35: 2.588 | K35: 2.605 | L35: 2.605 | M35: 0 | N35: 2.616 | O35: -0.011 | P35: -0.4
A36: 35 | B36: longitudinal_extreme | C36: 2.7172 | D36: 0 | E36: bottle | F36: 0.72 | G36: 640 | H36: 224 | I36: 2.561 | J36: 2.636 | K36: 2.656 | L36: 2.656 | M36: 0 | N36: 2.667 | O36: -0.011 | P36: -0.4
A37: 36 | B37: longitudinal_extreme | C37: 2.7677 | D37: 0 | E37: bottle | F37: 0.62 | G37: 640 | H37: 223 | I37: 2.609 | J37: 2.684 | K37: 2.706 | L37: 2.706 | M37: 0 | N37: 2.717 | O37: -0.011 | P37: -0.4
A38: 37 | B38: longitudinal_extreme | C38: 2.8182 | D38: 0
A39: 38 | B39: longitudinal_extreme | C39: 2.8687 | D39: 0 | E39: bottle | F39: 0.44 | G39: 640 | H39: 219 | I39: 2.704 | J39: 2.779 | K39: 2.808 | L39: 2.808 | M39: 0 | N39: 2.818 | O39: -0.011 | P39: -0.4
A40: 39 | B40: longitudinal_extreme | C40: 2.9192 | D40: 0 | E40: bottle | F40: 0.45 | G40: 640 | H40: 217 | I40: 2.751 | J40: 2.826 | K40: 2.858 | L40: 2.858 | M40: 0 | N40: 2.869 | O40: -0.01 | P40: -0.4
...

Sheet Clutter Trials
A1: trial | B1: scene | C1: x_m | D1: y_m | E1: detection | F1: confidence | G1: pixel_u | H1: pixel_v | I1: depth_surface_m | J1: depth_center_m | K1: estimated_ground_m | L1: estimated_forward_m | M1: estimated_lateral_m | N1: ground_truth_m | O1: error_m | P1: error_pct
A2: 1 | B2: clutter_longitudinal | C2: 1 | D2: 0
A3: 2 | B3: clutter_longitudinal | C3: 1.5 | D3: 0 | E3: bottle | F3: 0.5 | G3: 640 | H3: 394 | I3: 0.992 | J3: 1.067 | K3: 0.982 | L3: 0.982 | M3: 0 | N3: 1.5 | O3: -0.518 | P3: -34.5
A4: 3 | B4: clutter_longitudinal | C4: 2 | D4: 0 | E4: bottle | F4: 0.27 | G4: 640 | H4: 306 | I4: 1.464 | J4: 1.539 | K4: 1.486 | L4: 1.486 | M4: 0 | N4: 1.5 | O4: -0.014 | P4: -1
A5: 4 | B5: clutter_longitudinal | C5: 2.5 | D5: 0 | E5: bottle | F5: 0.62 | G5: 639 | H5: 258 | I5: 1.932 | J5: 2.007 | K5: 1.988 | L5: 1.988 | M5: 0.003 | N5: 2 | O5: -0.012 | P5: -0.6
A6: 5 | B6: clutter_longitudinal | C6: 3 | D6: 0
A7: 6 | B7: clutter_longitudinal | C7: 3.5 | D7: 0
A8: 7 | B8: clutter_longitudinal | C8: 4 | D8: 0 | E8: bottle | F8: 0.35 | G8: 640 | H8: 196 | I8: 3.34 | J8: 3.415 | K8: 3.491 | L8: 3.491 | M8: 0 | N8: 3.5 | O8: -0.009 | P8: -0.3
A9: 8 | B9: clutter_longitudinal | C9: 4.5 | D9: 0
A10: 9 | B10: clutter_longitudinal | C10: 5 | D10: 0
A11: 10 | B11: clutter_longitudinal | C11: 5.5 | D11: 0
A12: 11 | B12: clutter_longitudinal | C12: 6 | D12: 0
A13: 12 | B13: clutter_lateral | C13: 3 | D13: -1.5
A14: 14 | B14: clutter_lateral | C14: 3 | D14: -0.5
A15: 15 | B15: clutter_lateral | C15: 3 | D15: 0
A16: 16 | B16: clutter_lateral | C16: 3 | D16: 0.5
A17: 17 | B17: clutter_lateral | C17: 3 | D17: 1
A18: 18 | B18: clutter_lateral | C18: 3 | D18: 1.5
A19: 31 | B19: clutter_close_center | C19: 1.2 | D19: 0 | E19: bottle | F19: 0.29 | G19: 640 | H19: 210 | I19: 2.871 | J19: 2.946 | K19: 2.99 | L19: 2.99 | M19: 0 | N19: 3 | O19: -0.01 | P19: -0.3
A20: 32 | B20: clutter_close_center | C20: 1.5 | D20: 0 | E20: bottle | F20: 0.6 | G20: 640 | H20: 351 | I20: 1.181 | J20: 1.256 | K20: 1.184 | L20: 1.184 | M20: 0 | N20: 1.2 | O20: -0.016 | P20: -1.3
A21: 33 | B21: clutter_close_center | C21: 1.8 | D21: 0
A22: 34 | B22: clutter_close_center | C22: 2 | D22: 0 | E22: bottle | F22: 0.69 | G22: 640 | H22: 275 | I22: 1.746 | J22: 1.821 | K22: 1.787 | L22: 1.787 | M22: 0 | N22: 1.8 | O22: -0.013 | P22: -0.7
A23: 35 | B23: clutter_close_center | C23: 2.3 | D23: 0 | E23: bottle | F23: 0.7 | G23: 639 | H23: 258 | I23: 1.932 | J23: 2.007 | K23: 1.988 | L23: 1.988 | M23: 0.003 | N23: 2 | O23: -0.012 | P23: -0.6
A24: 36 | B24: clutter_mid_center | C24: 2.5 | D24: 0 | E24: bottle | F24: 0.33 | G24: 640 | H24: 245 | I24: 2.22 | J24: 2.295 | K24: 2.288 | L24: 2.288 | M24: 0 | N24: 2.3 | O24: -0.012 | P24: -0.5
A25: 37 | B25: clutter_mid_center | C25: 2.8 | D25: 0
A26: 38 | B26: clutter_mid_center | C26: 3 | D26: 0
A27: 39 | B27: clutter_mid_center | C27: 3.2 | D27: 0 | E27: bottle | F27: 0.29 | G27: 640 | H27: 210 | I27: 2.871 | J27: 2.946 | K27: 2.99 | L27: 2.99 | M27: 0 | N27: 3 | O27: -0.01 | P27: -0.3
A28: 40 | B28: clutter_mid_center | C28: 3.5 | D28: 0 | E28: bottle | F28: 0.35 | G28: 640 | H28: 196 | I28: 3.34 | J28: 3.415 | K28: 3.491 | L28: 3.491 | M28: 0 | N28: 3.5 | O28: -0.009 | P28: -0.3
A29: 41 | B29: clutter_far_center | C29: 4 | D29: 0 | E29: bottle | F29: 0.35 | G29: 640 | H29: 196 | I29: 3.829 | J29: 3.904 | K29: 3.991 | L29: 3.991 | M29: 0 | N29: 4 | O29: -0.009 | P29: -0.2
A30: 42 | B30: clutter_far_center | C30: 4.5 | D30: 0
A31: 43 | B31: clutter_far_center | C31: 5 | D31: 0
A32: 44 | B32: clutter_lateral_2m | C32: 2 | D32: -0.3
A33: 45 | B33: clutter_lateral_2m | C33: 2 | D33: 0 | E33: bottle | F33: 0.65 | G33: 739 | H33: 259 | I33: 1.935 | J33: 2.01 | K33: 2.011 | L33: 1.989 | M33: -0.295 | N33: 2.022 | O33: -0.012 | P33: -0.6
A34: 46 | B34: clutter_lateral_2m | C34: 2 | D34: 0.3 | E34: bottle | F34: 0.65 | G34: 739 | H34: 259 | I34: 1.935 | J34: 2.01 | K34: 2.011 | L34: 1.989 | M34: -0.295 | N34: 2 | O34: 0.011 | P34: 0.5
A35: 47 | B35: clutter_lateral_3m | C35: 3 | D35: -0.5 | E35: bottle | F35: 0.7 | G35: 639 | H35: 258 | I35: 1.932 | J35: 2.007 | K35: 1.988 | L35: 1.988 | M35: 0.003 | N35: 2.022 | O35: -0.035 | P35: -1.7
A36: 48 | B36: clutter_lateral_3m | C36: 3 | D36: -0.3
A37: 49 | B37: clutter_lateral_3m | C37: 3 | D37: 0
A38: 50 | B38: clutter_lateral_3m | C38: 3 | D38: 0.3 | E38: bottle | F38: 0.29 | G38: 640 | H38: 210 | I38: 2.871 | J38: 2.946 | K38: 2.99 | L38: 2.99 | M38: 0 | N38: 3.015 | O38: -0.025 | P38: -0.8
A39: 51 | B39: clutter_lateral_3m | C39: 3 | D39: 0.5
A40: 52 | B40: clutter_lateral_4m | C40: 4 | D40: -0.5
...

Sheet Combined Metrics
A1: LIGHTING ROBUSTNESS (by brightness level)
A2: Group | B2: Trials | C2: Detections | D2: Det Rate | E2: Misses | F2: Mean Conf | G2: Mean Err (m) | H2: MAE (m) | I2: Median Err (m) | J2: Min Err (m) | K2: Max Err (m)
A3: 10 | B3: =COUNTIF('Lighting Trials'!$A$2:$A$383,$A3) -> 40 | C3: =COUNTIFS('Lighting Trials'!$A$2:$A$383,$A3,'Lighting Trials'!$F$2:$F$383,"<>") -> 18 | D3: =C3/B3 -> 0.45 | E3: =B3-C3 -> 22 | F3: =ROUND(AVERAGEIFS('Lighting Trials'!$G$2:$G$383,'Lighting Trials'!$A$2:$A$383,$A3,'Lighting Trials'!$F$2:$F$383,"<>"),4) -> 0.6633 | G3: =ROUND(AVERAGEIFS('Lighting Trials'!$P$2:$P$383,'Lighting Trials'!$A$2:$A$383,$A3,'Lighting Trials'!$F$2:$F$383,"<>"),4) -> -0.074 | H3: {=ROUND(AVERAGE(_xlfn._xlws.FILTER(ABS('Lighting Trials'!$P$2:$P$383),('Lighting Trials'!$A$2:$A$383=$A3)*('Lighting Trials'!$F$2:$F$383<>""))),4)} -> 0.0907 | I3: {=ROUND(MEDIAN(_xlfn._xlws.FILTER(ABS('Lighting Trials'!$P$2:$P$383),('Lighting Trials'!$A$2:$A$383=$A3)*('Lighting Trials'!$F$2:$F$383<>""))),4)} -> 0.012 | J3: {=ROUND(MIN(_xlfn._xlws.FILTER(ABS('Lighting Trials'!$P$2:$P$383),('Lighting Trials'!$A$2:$A$383=$A3)*('Lighting Trials'!$F$2:$F$383<>""))),4)} -> 0.007 | K3: {=ROUND(MAX(_xlfn._xlws.FILTER(ABS('Lighting Trials'!$P$2:$P$383),('Lighting Trials'!$A$2:$A$383=$A3)*('Lighting Trials'!$F$2:$F$383<>""))),4)} -> 0.274
A4: 20 | B4: =COUNTIF('Lighting Trials'!$A$2:$A$383,$A4) -> 40 | C4: =COUNTIFS('Lighting Trials'!$A$2:$A$383,$A4,'Lighting Trials'!$F$2:$F$383,"<>") -> 26 | D4: =C4/B4 -> 0.65 | E4: =B4-C4 -> 14 | F4: =ROUND(AVERAGEIFS('Lighting Trials'!$G$2:$G$383,'Lighting Trials'!$A$2:$A$383,$A4,'Lighting Trials'!$F$2:$F$383,"<>"),4) -> 0.6615 | G4: =ROUND(AVERAGEIFS('Lighting Trials'!$P$2:$P$383,'Lighting Trials'!$A$2:$A$383,$A4,'Lighting Trials'!$F$2:$F$383,"<>"),4) -> 0.0147 | H4: {=ROUND(AVERAGE(_xlfn._xlws.FILTER(ABS('Lighting Trials'!$P$2:$P$383),('Lighting Trials'!$A$2:$A$383=$A4)*('Lighting Trials'!$F$2:$F$383<>""))),4)} -> 0.0269 | I4: {=ROUND(MEDIAN(_xlfn._xlws.FILTER(ABS('Lighting Trials'!$P$2:$P$383),('Lighting Trials'!$A$2:$A$383=$A4)*('Lighting Trials'!$F$2:$F$383<>""))),4)} -> 0.009 | J4: {=ROUND(MIN(_xlfn._xlws.FILTER(ABS('Lighting Trials'!$P$2:$P$383),('Lighting Trials'!$A$2:$A$383=$A4)*('Lighting Trials'!$F$2:$F$383<>""))),4)} -> 0.001 | K4: {=ROUND(MAX(_xlfn._xlws.FILTER(ABS('Lighting Trials'!$P$2:$P$383),('Lighting Trials'!$A$2:$A$383=$A4)*('Lighting Trials'!$F$2:$F$383<>""))),4)} -> 0.255
A5: 30 | B5: =COUNTIF('Lighting Trials'!$A$2:$A$383,$A5) -> 22 | C5: =COUNTIFS('Lighting Trials'!$A$2:$A$383,$A5,'Lighting Trials'!$F$2:$F$383,"<>") -> 14 | D5: =C5/B5 -> 0.63636364 | E5: =B5-C5 -> 8 | F5: =ROUND(AVERAGEIFS('Lighting Trials'!$G$2:$G$383,'Lighting Trials'!$A$2:$A$383,$A5,'Lighting Trials'!$F$2:$F$383,"<>"),4) -> 0.6829 | G5: =ROUND(AVERAGEIFS('Lighting Trials'!$P$2:$P$383,'Lighting Trials'!$A$2:$A$383,$A5,'Lighting Trials'!$F$2:$F$383,"<>"),4) -> -0.0488 | H5: {=ROUND(AVERAGE(_xlfn._xlws.FILTER(ABS('Lighting Trials'!$P$2:$P$383),('Lighting Trials'!$A$2:$A$383=$A5)*('Lighting Trials'!$F$2:$F$383<>""))),4)} -> 0.0842 | I5: {=ROUND(MEDIAN(_xlfn._xlws.FILTER(ABS('Lighting Trials'!$P$2:$P$383),('Lighting Trials'!$A$2:$A$383=$A5)*('Lighting Trials'!$F$2:$F$383<>""))),4)} -> 0.0125 | J5: {=ROUND(MIN(_xlfn._xlws.FILTER(ABS('Lighting Trials'!$P$2:$P$383),('Lighting Trials'!$A$2:$A$383=$A5)*('Lighting Trials'!$F$2:$F$383<>""))),4)} -> 0.008 | K5: {=ROUND(MAX(_xlfn._xlws.FILTER(ABS('Lighting Trials'!$P$2:$P$383),('Lighting Trials'!$A$2:$A$383=$A5)*('Lighting Trials'!$F$2:$F$383<>""))),4)} -> 0.275
A6: 40 | B6: =COUNTIF('Lighting Trials'!$A$2:$A$383,$A6) -> 40 | C6: =COUNTIFS('Lighting Trials'!$A$2:$A$383,$A6,'Lighting Trials'!$F$2:$F$383,"<>") -> 22 | D6: =C6/B6 -> 0.55 | E6: =B6-C6 -> 18 | F6: =ROUND(AVERAGEIFS('Lighting Trials'!$G$2:$G$383,'Lighting Trials'!$A$2:$A$383,$A6,'Lighting Trials'!$F$2:$F$383,"<>"),4) -> 0.7359 | G6: =ROUND(AVERAGEIFS('Lighting Trials'!$P$2:$P$383,'Lighting Trials'!$A$2:$A$383,$A6,'Lighting Trials'!$F$2:$F$383,"<>"),4) -> 0.1319 | H6: {=ROUND(AVERAGE(_xlfn._xlws.FILTER(ABS('Lighting Trials'!$P$2:$P$383),('Lighting Trials'!$A$2:$A$383=$A6)*('Lighting Trials'!$F$2:$F$383<>""))),4)} -> 0.2194 | I6: {=ROUND(MEDIAN(_xlfn._xlws.FILTER(ABS('Lighting Trials'!$P$2:$P$383),('Lighting Trials'!$A$2:$A$383=$A6)*('Lighting Trials'!$F$2:$F$383<>""))),4)} -> 0.0115 | J6: {=ROUND(MIN(_xlfn._xlws.FILTER(ABS('Lighting Trials'!$P$2:$P$383),('Lighting Trials'!$A$2:$A$383=$A6)*('Lighting Trials'!$F$2:$F$383<>""))),4)} -> 0.002 | K6: {=ROUND(MAX(_xlfn._xlws.FILTER(ABS('Lighting Trials'!$P$2:$P$383),('Lighting Trials'!$A$2:$A$383=$A6)*('Lighting Trials'!$F$2:$F$383<>""))),4)} -> 2.107
A7: 50 | B7: =COUNTIF('Lighting Trials'!$A$2:$A$383,$A7) -> 40 | C7: =COUNTIFS('Lighting Trials'!$A$2:$A$383,$A7,'Lighting Trials'!$F$2:$F$383,"<>") -> 22 | D7: =C7/B7 -> 0.55 | E7: =B7-C7 -> 18 | F7: =ROUND(AVERAGEIFS('Lighting Trials'!$G$2:$G$383,'Lighting Trials'!$A$2:$A$383,$A7,'Lighting Trials'!$F$2:$F$383,"<>"),4) -> 0.74 | G7: =ROUND(AVERAGEIFS('Lighting Trials'!$P$2:$P$383,'Lighting Trials'!$A$2:$A$383,$A7,'Lighting Trials'!$F$2:$F$383,"<>"),4) -> -0.0156 | H7: {=ROUND(AVERAGE(_xlfn._xlws.FILTER(ABS('Lighting Trials'!$P$2:$P$383),('Lighting Trials'!$A$2:$A$383=$A7)*('Lighting Trials'!$F$2:$F$383<>""))),4)} -> 0.0209 | I7: {=ROUND(MEDIAN(_xlfn._xlws.FILTER(ABS('Lighting Trials'!$P$2:$P$383),('Lighting Trials'!$A$2:$A$383=$A7)*('Lighting Trials'!$F$2:$F$383<>""))),4)} -> 0.0095 | J7: {=ROUND(MIN(_xlfn._xlws.FILTER(ABS('Lighting Trials'!$P$2:$P$383),('Lighting Trials'!$A$2:$A$383=$A7)*('Lighting Trials'!$F$2:$F$383<>""))),4)} -> 0.002 | K7: {=ROUND(MAX(_xlfn._xlws.FILTER(ABS('Lighting Trials'!$P$2:$P$383),('Lighting Trials'!$A$2:$A$383=$A7)*('Lighting Trials'!$F$2:$F$383<>""))),4)} -> 0.271
A8: 60 | B8: =COUNTIF('Lighting Trials'!$A$2:$A$383,$A8) -> 40 | C8: =COUNTIFS('Lighting Trials'!$A$2:$A$383,$A8,'Lighting Trials'!$F$2:$F$383,"<>") -> 24 | D8: =C8/B8 -> 0.6 | E8: =B8-C8 -> 16 | F8: =ROUND(AVERAGEIFS('Lighting Trials'!$G$2:$G$383,'Lighting Trials'!$A$2:$A$383,$A8,'Lighting Trials'!$F$2:$F$383,"<>"),4) -> 0.7588 | G8: =ROUND(AVERAGEIFS('Lighting Trials'!$P$2:$P$383,'Lighting Trials'!$A$2:$A$383,$A8,'Lighting Trials'!$F$2:$F$383,"<>"),4) -> 0.0465 | H8: {=ROUND(AVERAGE(_xlfn._xlws.FILTER(ABS('Lighting Trials'!$P$2:$P$383),('Lighting Trials'!$A$2:$A$383=$A8)*('Lighting Trials'!$F$2:$F$383<>""))),4)} -> 0.1458 | I8: {=ROUND(MEDIAN(_xlfn._xlws.FILTER(ABS('Lighting Trials'!$P$2:$P$383),('Lighting Trials'!$A$2:$A$383=$A8)*('Lighting Trials'!$F$2:$F$383<>""))),4)} -> 0.0135 | J8: {=ROUND(MIN(_xlfn._xlws.FILTER(ABS('Lighting Trials'!$P$2:$P$383),('Lighting Trials'!$A$2:$A$383=$A8)*('Lighting Trials'!$F$2:$F$383<>""))),4)} -> 0.002 | K8: {=ROUND(MAX(_xlfn._xlws.FILTER(ABS('Lighting Trials'!$P$2:$P$383),('Lighting Trials'!$A$2:$A$383=$A8)*('Lighting Trials'!$F$2:$F$383<>""))),4)} -> 1.713
A9: 70 | B9: =COUNTIF('Lighting Trials'!$A$2:$A$383,$A9) -> 40 | C9: =COUNTIFS('Lighting Trials'!$A$2:$A$383,$A9,'Lighting Trials'!$F$2:$F$383,"<>") -> 25 | D9: =C9/B9 -> 0.625 | E9: =B9-C9 -> 15 | F9: =ROUND(AVERAGEIFS('Lighting Trials'!$G$2:$G$383,'Lighting Trials'!$A$2:$A$383,$A9,'Lighting Trials'!$F$2:$F$383,"<>"),4) -> 0.7436 | G9: =ROUND(AVERAGEIFS('Lighting Trials'!$P$2:$P$383,'Lighting Trials'!$A$2:$A$383,$A9,'Lighting Trials'!$F$2:$F$383,"<>"),4) -> -0.0222 | H9: {=ROUND(AVERAGE(_xlfn._xlws.FILTER(ABS('Lighting Trials'!$P$2:$P$383),('Lighting Trials'!$A$2:$A$383=$A9)*('Lighting Trials'!$F$2:$F$383<>""))),4)} -> 0.0452 | I9: {=ROUND(MEDIAN(_xlfn._xlws.FILTER(ABS('Lighting Trials'!$P$2:$P$383),('Lighting Trials'!$A$2:$A$383=$A9)*('Lighting Trials'!$F$2:$F$383<>""))),4)} -> 0.011 | J9: {=ROUND(MIN(_xlfn._xlws.FILTER(ABS('Lighting Trials'!$P$2:$P$383),('Lighting Trials'!$A$2:$A$383=$A9)*('Lighting Trials'!$F$2:$F$383<>""))),4)} -> 0.002 | K9: {=ROUND(MAX(_xlfn._xlws.FILTER(ABS('Lighting Trials'!$P$2:$P$383),('Lighting Trials'!$A$2:$A$383=$A9)*('Lighting Trials'!$F$2:$F$383<>""))),4)} -> 0.275
A10: 80 | B10: =COUNTIF('Lighting Trials'!$A$2:$A$383,$A10) -> 40 | C10: =COUNTIFS('Lighting Trials'!$A$2:$A$383,$A10,'Lighting Trials'!$F$2:$F$383,"<>") -> 30 | D10: =C10/B10 -> 0.75 | E10: =B10-C10 -> 10 | F10: =ROUND(AVERAGEIFS('Lighting Trials'!$G$2:$G$383,'Lighting Trials'!$A$2:$A$383,$A10,'Lighting Trials'!$F$2:$F$383,"<>"),4) -> 0.737 | G10: =ROUND(AVERAGEIFS('Lighting Trials'!$P$2:$P$383,'Lighting Trials'!$A$2:$A$383,$A10,'Lighting Trials'!$F$2:$F$383,"<>"),4) -> -0.0269 | H10: {=ROUND(AVERAGE(_xlfn._xlws.FILTER(ABS('Lighting Trials'!$P$2:$P$383),('Lighting Trials'!$A$2:$A$383=$A10)*('Lighting Trials'!$F$2:$F$383<>""))),4)} -> 0.0611 | I10: {=ROUND(MEDIAN(_xlfn._xlws.FILTER(ABS('Lighting Trials'!$P$2:$P$383),('Lighting Trials'!$A$2:$A$383=$A10)*('Lighting Trials'!$F$2:$F$383<>""))),4)} -> 0.0115 | J10: {=ROUND(MIN(_xlfn._xlws.FILTER(ABS('Lighting Trials'!$P$2:$P$383),('Lighting Trials'!$A$2:$A$383=$A10)*('Lighting Trials'!$F$2:$F$383<>""))),4)} -> 0.001 | K10: {=ROUND(MAX(_xlfn._xlws.FILTER(ABS('Lighting Trials'!$P$2:$P$383),('Lighting Trials'!$A$2:$A$383=$A10)*('Lighting Trials'!$F$2:$F$383<>""))),4)} -> 0.275
A11: 90 | B11: =COUNTIF('Lighting Trials'!$A$2:$A$383,$A11) -> 40 | C11: =COUNTIFS('Lighting Trials'!$A$2:$A$383,$A11,'Lighting Trials'!$F$2:$F$383,"<>") -> 29 | D11: =C11/B11 -> 0.725 | E11: =B11-C11 -> 11 | F11: =ROUND(AVERAGEIFS('Lighting Trials'!$G$2:$G$383,'Lighting Trials'!$A$2:$A$383,$A11,'Lighting Trials'!$F$2:$F$383,"<>"),4) -> 0.7238 | G11: =ROUND(AVERAGEIFS('Lighting Trials'!$P$2:$P$383,'Lighting Trials'!$A$2:$A$383,$A11,'Lighting Trials'!$F$2:$F$383,"<>"),4) -> -0.0078 | H11: {=ROUND(AVERAGE(_xlfn._xlws.FILTER(ABS('Lighting Trials'!$P$2:$P$383),('Lighting Trials'!$A$2:$A$383=$A11)*('Lighting Trials'!$F$2:$F$383<>""))),4)} -> 0.042 | I11: {=ROUND(MEDIAN(_xlfn._xlws.FILTER(ABS('Lighting Trials'!$P$2:$P$383),('Lighting Trials'!$A$2:$A$383=$A11)*('Lighting Trials'!$F$2:$F$383<>""))),4)} -> 0.011 | J11: {=ROUND(MIN(_xlfn._xlws.FILTER(ABS('Lighting Trials'!$P$2:$P$383),('Lighting Trials'!$A$2:$A$383=$A11)*('Lighting Trials'!$F$2:$F$383<>""))),4)} -> 0.001 | K11: {=ROUND(MAX(_xlfn._xlws.FILTER(ABS('Lighting Trials'!$P$2:$P$383),('Lighting Trials'!$A$2:$A$383=$A11)*('Lighting Trials'!$F$2:$F$383<>""))),4)} -> 0.274
A12: 100 | B12: =COUNTIF('Lighting Trials'!$A$2:$A$383,$A12) -> 40 | C12: =COUNTIFS('Lighting Trials'!$A$2:$A$383,$A12,'Lighting Trials'!$F$2:$F$383,"<>") -> 25 | D12: =C12/B12 -> 0.625 | E12: =B12-C12 -> 15 | F12: =ROUND(AVERAGEIFS('Lighting Trials'!$G$2:$G$383,'Lighting Trials'!$A$2:$A$383,$A12,'Lighting Trials'!$F$2:$F$383,"<>"),4) -> 0.704 | G12: =ROUND(AVERAGEIFS('Lighting Trials'!$P$2:$P$383,'Lighting Trials'!$A$2:$A$383,$A12,'Lighting Trials'!$F$2:$F$383,"<>"),4) -> 0.069 | H12: {=ROUND(AVERAGE(_xlfn._xlws.FILTER(ABS('Lighting Trials'!$P$2:$P$383),('Lighting Trials'!$A$2:$A$383=$A12)*('Lighting Trials'!$F$2:$F$383<>""))),4)} -> 0.1424 | I12: {=ROUND(MEDIAN(_xlfn._xlws.FILTER(ABS('Lighting Trials'!$P$2:$P$383),('Lighting Trials'!$A$2:$A$383=$A12)*('Lighting Trials'!$F$2:$F$383<>""))),4)} -> 0.012 | J12: {=ROUND(MIN(_xlfn._xlws.FILTER(ABS('Lighting Trials'!$P$2:$P$383),('Lighting Trials'!$A$2:$A$383=$A12)*('Lighting Trials'!$F$2:$F$383<>""))),4)} -> 0.001 | K12: {=ROUND(MAX(_xlfn._xlws.FILTER(ABS('Lighting Trials'!$P$2:$P$383),('Lighting Trials'!$A$2:$A$383=$A12)*('Lighting Trials'!$F$2:$F$383<>""))),4)} -> 2.103
A14: LIGHTING OVERALL
A15: Group | B15: Trials | C15: Detections | D15: Det Rate | E15: Misses | F15: Mean Conf | G15: Mean Err (m) | H15: MAE (m) | I15: Median Err (m) | J15: Min Err (m) | K15: Max Err (m)
A16: Lighting Overall | B16: =COUNTA('Lighting Trials'!$A$2:$A$383) -> 382 | C16: =COUNTIF('Lighting Trials'!$F$2:$F$383,"<>") -> 235 | D16: =C16/B16 -> 0.61518325 | E16: =B16-C16 -> 147 | F16: {=ROUND(AVERAGE(_xlfn._xlws.FILTER('Lighting Trials'!$G$2:$G$383,('Lighting Trials'!$F$2:$F$383<>""))),4)} -> 0.7177 | G16: {=ROUND(AVERAGE(_xlfn._xlws.FILTER('Lighting Trials'!$P$2:$P$383,('Lighting Trials'!$F$2:$F$383<>""))),4)} -> 0.0093 | H16: {=ROUND(AVERAGE(_xlfn._xlws.FILTER(ABS('Lighting Trials'!$P$2:$P$383),('Lighting Trials'!$F$2:$F$383<>""))),4)} -> 0.0853 | I16: {=ROUND(MEDIAN(_xlfn._xlws.FILTER(ABS('Lighting Trials'!$P$2:$P$383),('Lighting Trials'!$F$2:$F$383<>""))),4)} -> 0.01 | J16: {=ROUND(MIN(_xlfn._xlws.FILTER(ABS('Lighting Trials'!$P$2:$P$383),('Lighting Trials'!$F$2:$F$383<>""))),4)} -> 0.001 | K16: {=ROUND(MAX(_xlfn._xlws.FILTER(ABS('Lighting Trials'!$P$2:$P$383),('Lighting Trials'!$F$2:$F$383<>""))),4)} -> 2.107
A18: BASELINE ACCURACY (by sweep type)
A19: Group | B19: Trials | C19: Detections | D19: Det Rate | E19: Misses | F19: Mean Conf | G19: Mean Err (m) | H19: MAE (m) | I19: Median Err (m) | J19: Min Err (m) | K19: Max Err (m)
A20: lateral_extreme | B20: =COUNTIF('Baseline Trials'!$B$2:$B$171,$A20) -> 70 | C20: =COUNTIFS('Baseline Trials'!$B$2:$B$171,$A20,'Baseline Trials'!$E$2:$E$171,"<>") -> 49 | D20: =C20/B20 -> 0.7 | E20: =B20-C20 -> 21 | F20: =ROUND(AVERAGEIFS('Baseline Trials'!$F$2:$F$171,'Baseline Trials'!$B$2:$B$171,$A20,'Baseline Trials'!$E$2:$E$171,"<>"),4) -> 0.7541 | G20: =ROUND(AVERAGEIFS('Baseline Trials'!$O$2:$O$171,'Baseline Trials'!$B$2:$B$171,$A20,'Baseline Trials'!$E$2:$E$171,"<>"),4) -> 0.1056 | H20: {=ROUND(AVERAGE(_xlfn._xlws.FILTER(ABS('Baseline Trials'!$O$2:$O$171),('Baseline Trials'!$B$2:$B$171=$A20)*('Baseline Trials'!$E$2:$E$171<>""))),4)} -> 0.125 | I20: {=ROUND(MEDIAN(_xlfn._xlws.FILTER(ABS('Baseline Trials'!$O$2:$O$171),('Baseline Trials'!$B$2:$B$171=$A20)*('Baseline Trials'!$E$2:$E$171<>""))),4)} -> 0.01 | J20: {=ROUND(MIN(_xlfn._xlws.FILTER(ABS('Baseline Trials'!$O$2:$O$171),('Baseline Trials'!$B$2:$B$171=$A20)*('Baseline Trials'!$E$2:$E$171<>""))),4)} -> 0 | K20: {=ROUND(MAX(_xlfn._xlws.FILTER(ABS('Baseline Trials'!$O$2:$O$171),('Baseline Trials'!$B$2:$B$171=$A20)*('Baseline Trials'!$E$2:$E$171<>""))),4)} -> 1.761
A21: longitudinal_extreme | B21: =COUNTIF('Baseline Trials'!$B$2:$B$171,$A21) -> 100 | C21: =COUNTIFS('Baseline Trials'!$B$2:$B$171,$A21,'Baseline Trials'!$E$2:$E$171,"<>") -> 78 | D21: =C21/B21 -> 0.78 | E21: =B21-C21 -> 22 | F21: =ROUND(AVERAGEIFS('Baseline Trials'!$F$2:$F$171,'Baseline Trials'!$B$2:$B$171,$A21,'Baseline Trials'!$E$2:$E$171,"<>"),4) -> 0.6354 | G21: =ROUND(AVERAGEIFS('Baseline Trials'!$O$2:$O$171,'Baseline Trials'!$B$2:$B$171,$A21,'Baseline Trials'!$E$2:$E$171,"<>"),4) -> -0.0195 | H21: {=ROUND(AVERAGE(_xlfn._xlws.FILTER(ABS('Baseline Trials'!$O$2:$O$171),('Baseline Trials'!$B$2:$B$171=$A21)*('Baseline Trials'!$E$2:$E$171<>""))),4)} -> 0.0213 | I21: {=ROUND(MEDIAN(_xlfn._xlws.FILTER(ABS('Baseline Trials'!$O$2:$O$171),('Baseline Trials'!$B$2:$B$171=$A21)*('Baseline Trials'!$E$2:$E$171<>""))),4)} -> 0.011 | J21: {=ROUND(MIN(_xlfn._xlws.FILTER(ABS('Baseline Trials'!$O$2:$O$171),('Baseline Trials'!$B$2:$B$171=$A21)*('Baseline Trials'!$E$2:$E$171<>""))),4)} -> 0.007 | K21: {=ROUND(MAX(_xlfn._xlws.FILTER(ABS('Baseline Trials'!$O$2:$O$171),('Baseline Trials'!$B$2:$B$171=$A21)*('Baseline Trials'!$E$2:$E$171<>""))),4)} -> 0.067
A23: BASELINE OVERALL
A24: Group | B24: Trials | C24: Detections | D24: Det Rate | E24: Misses | F24: Mean Conf | G24: Mean Err (m) | H24: MAE (m) | I24: Median Err (m) | J24: Min Err (m) | K24: Max Err (m)
A25: Baseline Overall | B25: =COUNTA('Baseline Trials'!$B$2:$B$171) -> 170 | C25: =COUNTIF('Baseline Trials'!$E$2:$E$171,"<>") -> 127 | D25: =C25/B25 -> 0.74705882 | E25: =B25-C25 -> 43 | F25: {=ROUND(AVERAGE(_xlfn._xlws.FILTER('Baseline Trials'!$F$2:$F$171,('Baseline Trials'!$E$2:$E$171<>""))),4)} -> 0.6812 | G25: {=ROUND(AVERAGE(_xlfn._xlws.FILTER('Baseline Trials'!$O$2:$O$171,('Baseline Trials'!$E$2:$E$171<>""))),4)} -> 0.0288 | H25: {=ROUND(AVERAGE(_xlfn._xlws.FILTER(ABS('Baseline Trials'!$O$2:$O$171),('Baseline Trials'!$E$2:$E$171<>""))),4)} -> 0.0613 | I25: {=ROUND(MEDIAN(_xlfn._xlws.FILTER(ABS('Baseline Trials'!$O$2:$O$171),('Baseline Trials'!$E$2:$E$171<>""))),4)} -> 0.011 | J25: {=ROUND(MIN(_xlfn._xlws.FILTER(ABS('Baseline Trials'!$O$2:$O$171),('Baseline Trials'!$E$2:$E$171<>""))),4)} -> 0 | K25: {=ROUND(MAX(_xlfn._xlws.FILTER(ABS('Baseline Trials'!$O$2:$O$171),('Baseline Trials'!$E$2:$E$171<>""))),4)} -> 1.761
A27: CLUTTER ORIGINAL (41 trials)
A28: Group | B28: Trials | C28: Detections | D28: Det Rate | E28: Misses | F28: Mean Conf | G28: Mean Err (m) | H28: MAE (m) | I28: Median Err (m) | J28: Min Err (m) | K28: Max Err (m)
A29: clutter_lateral | B29: {=SUM(COUNTIF('Clutter Trials'!$B$2:$B$42,{"clutter_lateral","clutter_lateral_2m","clutter_lateral_3m","clutter_lateral_4m"}))} -> 17 | C29: {=SUM(COUNTIFS('Clutter Trials'!$B$2:$B$42,{"clutter_lateral","clutter_lateral_2m","clutter_lateral_3m","clutter_lateral_4m"},'Clutter Trials'!$E$2:$E$42,"<>"))} -> 5 | D29: =C29/B29 -> 0.29411765 | E29: =B29-C29 -> 12 | F29: {=ROUND(AVERAGE(_xlfn._xlws.FILTER('Clutter Trials'!$F$2:$F$42,ISNUMBER(MATCH('Clutter Trials'!$B$2:$B$42,{"clutter_lateral","clutter_lateral_2m","clutter_lateral_3m","clutter_lateral_4m"},0))*('Clutter Trials'!$E$2:$E$42<>""))),4)} -> 0.548 | G29: {=ROUND(AVERAGE(_xlfn._xlws.FILTER('Clutter Trials'!$O$2:$O$42,ISNUMBER(MATCH('Clutter Trials'!$B$2:$B$42,{"clutter_lateral","clutter_lateral_2m","clutter_lateral_3m","clutter_lateral_4m"},0))*('Clutter Trials'!$E$2:$E$42<>""))),4)} -> -0.0076 | H29: {=ROUND(AVERAGE(_xlfn._xlws.FILTER(ABS('Clutter Trials'!$O$2:$O$42),ISNUMBER(MATCH('Clutter Trials'!$B$2:$B$42,{"clutter_lateral","clutter_lateral_2m","clutter_lateral_3m","clutter_lateral_4m"},0))*('Clutter Trials'!$E$2:$E$42<>""))),4)} -> 0.0212 | I29: {=ROUND(MEDIAN(_xlfn._xlws.FILTER(ABS('Clutter Trials'!$O$2:$O$42),ISNUMBER(MATCH('Clutter Trials'!$B$2:$B$42,{"clutter_lateral","clutter_lateral_2m","clutter_lateral_3m","clutter_lateral_4m"},0))*('Clutter Trials'!$E$2:$E$42<>""))),4)} -> 0.023 | J29: {=ROUND(MIN(_xlfn._xlws.FILTER(ABS('Clutter Trials'!$O$2:$O$42),ISNUMBER(MATCH('Clutter Trials'!$B$2:$B$42,{"clutter_lateral","clutter_lateral_2m","clutter_lateral_3m","clutter_lateral_4m"},0))*('Clutter Trials'!$E$2:$E$42<>""))),4)} -> 0.011 | K29: {=ROUND(MAX(_xlfn._xlws.FILTER(ABS('Clutter Trials'!$O$2:$O$42),ISNUMBER(MATCH('Clutter Trials'!$B$2:$B$42,{"clutter_lateral","clutter_lateral_2m","clutter_lateral_3m","clutter_lateral_4m"},0))*('Clutter Trials'!$E$2:$E$42<>""))),4)} -> 0.035
A30: clutter_longitudinal | B30: {=SUM(COUNTIF('Clutter Trials'!$B$2:$B$42,{"clutter_longitudinal","clutter_close_center","clutter_mid_center","clutter_far_center"}))} -> 24 | C30: {=SUM(COUNTIFS('Clutter Trials'!$B$2:$B$42,{"clutter_longitudinal","clutter_close_center","clutter_mid_center","clutter_far_center"},'Clutter Trials'!$E$2:$E$42,"<>"))} -> 12 | D30: =C30/B30 -> 0.5 | E30: =B30-C30 -> 12 | F30: {=ROUND(AVERAGE(_xlfn._xlws.FILTER('Clutter Trials'!$F$2:$F$42,ISNUMBER(MATCH('Clutter Trials'!$B$2:$B$42,{"clutter_longitudinal","clutter_close_center","clutter_mid_center","clutter_far_center"},0))*('Clutter Trials'!$E$2:$E$42<>""))),4)} -> 0.445 | G30: {=ROUND(AVERAGE(_xlfn._xlws.FILTER('Clutter Trials'!$O$2:$O$42,ISNUMBER(MATCH('Clutter Trials'!$B$2:$B$42,{"clutter_longitudinal","clutter_close_center","clutter_mid_center","clutter_far_center"},0))*('Clutter Trials'!$E$2:$E$42<>""))),4)} -> -0.0537 | H30: {=ROUND(AVERAGE(_xlfn._xlws.FILTER(ABS('Clutter Trials'!$O$2:$O$42),ISNUMBER(MATCH('Clutter Trials'!$B$2:$B$42,{"clutter_longitudinal","clutter_close_center","clutter_mid_center","clutter_far_center"},0))*('Clutter Trials'!$E$2:$E$42<>""))),4)} -> 0.0537 | I30: {=ROUND(MEDIAN(_xlfn._xlws.FILTER(ABS('Clutter Trials'!$O$2:$O$42),ISNUMBER(MATCH('Clutter Trials'!$B$2:$B$42,{"clutter_longitudinal","clutter_close_center","clutter_mid_center","clutter_far_center"},0))*('Clutter Trials'!$E$2:$E$42<>""))),4)} -> 0.012 | J30: {=ROUND(MIN(_xlfn._xlws.FILTER(ABS('Clutter Trials'!$O$2:$O$42),ISNUMBER(MATCH('Clutter Trials'!$B$2:$B$42,{"clutter_longitudinal","clutter_close_center","clutter_mid_center","clutter_far_center"},0))*('Clutter Trials'!$E$2:$E$42<>""))),4)} -> 0.009 | K30: {=ROUND(MAX(_xlfn._xlws.FILTER(ABS('Clutter Trials'!$O$2:$O$42),ISNUMBER(MATCH('Clutter Trials'!$B$2:$B$42,{"clutter_longitudinal","clutter_close_center","clutter_mid_center","clutter_far_center"},0))*('Clutter Trials'!$E$2:$E$42<>""))),4)} -> 0.518
A32: CLUTTER OVERALL
A33: Group | B33: Trials | C33: Detections | D33: Det Rate | E33: Misses | F33: Mean Conf | G33: Mean Err (m) | H33: MAE (m) | I33: Median Err (m) | J33: Min Err (m) | K33: Max Err (m)
A34: All Clutter | B34: =COUNTA('Clutter Trials'!$B$2:$B$42) -> 41 | C34: =COUNTIF('Clutter Trials'!$E$2:$E$42,"<>") -> 17 | D34: =C34/B34 -> 0.41463415 | E34: =B34-C34 -> 24 | F34: {=ROUND(AVERAGE(_xlfn._xlws.FILTER('Clutter Trials'!$F$2:$F$42,('Clutter Trials'!$E$2:$E$42<>""))),4)} -> 0.4753 | G34: {=ROUND(AVERAGE(_xlfn._xlws.FILTER('Clutter Trials'!$O$2:$O$42,('Clutter Trials'!$E$2:$E$42<>""))),4)} -> -0.0401 | H34: {=ROUND(AVERAGE(_xlfn._xlws.FILTER(ABS('Clutter Trials'!$O$2:$O$42),('Clutter Trials'!$E$2:$E$42<>""))),4)} -> 0.0441 | I34: {=ROUND(MEDIAN(_xlfn._xlws.FILTER(ABS('Clutter Trials'!$O$2:$O$42),('Clutter Trials'!$E$2:$E$42<>""))),4)} -> 0.012 | J34: {=ROUND(MIN(_xlfn._xlws.FILTER(ABS('Clutter Trials'!$O$2:$O$42),('Clutter Trials'!$E$2:$E$42<>""))),4)} -> 0.009 | K34: {=ROUND(MAX(_xlfn._xlws.FILTER(ABS('Clutter Trials'!$O$2:$O$42),('Clutter Trials'!$E$2:$E$42<>""))),4)} -> 0.518
A36: GRAND TOTAL
A37: Group | B37: Trials | C37: Detections | D37: Det Rate | E37: Misses | F37: Mean Conf | G37: Mean Err (m) | H37: MAE (m) | I37: Median Err (m) | J37: Min Err (m) | K37: Max Err (m)
A38: ALL TESTS | B38: =SUM(B16,B25,B34) -> 593 | C38: =SUM(C16,C25,C34) -> 379 | D38: =C38/B38 -> 0.6391231 | E38: =B38-C38 -> 214 | F38: {=ROUND(AVERAGE(_xlfn.VSTACK(_xlfn._xlws.FILTER('Lighting Trials'!$G$2:$G$383,'Lighting Trials'!$F$2:$F$383<>""),_xlfn._xlws.FILTER('Baseline Trials'!$F$2:$F$171,'Baseline Trials'!$E$2:$E$171<>""),_xlfn._xlws.FILTER('Clutter Trials'!$F$2:$F$42,'Clutter Trials'!$E$2:$E$42<>""))),4)} -> 0.6946 | G38: {=ROUND(AVERAGE(_xlfn.VSTACK(_xlfn._xlws.FILTER('Lighting Trials'!$P$2:$P$383,'Lighting Trials'!$F$2:$F$383<>""),_xlfn._xlws.FILTER('Baseline Trials'!$O$2:$O$171,'Baseline Trials'!$E$2:$E$171<>""),_xlfn._xlws.FILTER('Clutter Trials'!$O$2:$O$42,'Clutter Trials'!$E$2:$E$42<>""))),4)} -> 0.0136 | H38: {=ROUND(AVERAGE(ABS(_xlfn.VSTACK(_xlfn._xlws.FILTER('Lighting Trials'!$P$2:$P$383,'Lighting Trials'!$F$2:$F$383<>""),_xlfn._xlws.FILTER('Baseline Trials'!$O$2:$O$171,'Baseline Trials'!$E$2:$E$171<>""),_xlfn._xlws.FILTER('Clutter Trials'!$O$2:$O$42,'Clutter Trials'!$E$2:$E$42<>"")))),4)} -> 0.0754 | I38: {=ROUND(MEDIAN(ABS(_xlfn.VSTACK(_xlfn._xlws.FILTER('Lighting Trials'!$P$2:$P$383,'Lighting Trials'!$F$2:$F$383<>""),_xlfn._xlws.FILTER('Baseline Trials'!$O$2:$O$171,'Baseline Trials'!$E$2:$E$171<>""),_xlfn._xlws.FILTER('Clutter Trials'!$O$2:$O$42,'Clutter Trials'!$E$2:$E$42<>"")))),4)} -> 0.011 | J38: =MIN(J16,J25,J34) -> 0 | K38: =MAX(K16,K25,K34) -> 2.107
A44: OVERALL
A45: Group | B45: Trials | C45: Detections | D45: Det Rate | E45: Misses | F45: Mean Conf | G45: Mean Err (m) | H45: MAE (m) | I45: Median Err (m) | J45: Min Err (m) | K45: Max Err (m)
A46: All Clutter | B46: =COUNTA('Clutter Trials'!$B$2:$B$42) -> 41 | C46: =COUNTIF('Clutter Trials'!$E$2:$E$42,"<>") -> 17 | D46: =C46/B46 -> 0.41463415 | E46: =B46-C46 -> 24 | F46: {=ROUND(AVERAGE(_xlfn._xlws.FILTER('Clutter Trials'!$F$2:$F$42,('Clutter Trials'!$E$2:$E$42<>""))),4)} -> 0.4753 | G46: {=ROUND(AVERAGE(_xlfn._xlws.FILTER('Clutter Trials'!$O$2:$O$42,('Clutter Trials'!$E$2:$E$42<>""))),4)} -> -0.0401 | H46: {=ROUND(AVERAGE(_xlfn._xlws.FILTER(ABS('Clutter Trials'!$O$2:$O$42),('Clutter Trials'!$E$2:$E$42<>""))),4)} -> 0.0441 | I46: {=ROUND(MEDIAN(_xlfn._xlws.FILTER(ABS('Clutter Trials'!$O$2:$O$42),('Clutter Trials'!$E$2:$E$42<>""))),4)} -> 0.012 | J46: {=ROUND(MIN(_xlfn._xlws.FILTER(ABS('Clutter Trials'!$O$2:$O$42),('Clutter Trials'!$E$2:$E$42<>""))),4)} -> 0.009 | K46: {=ROUND(MAX(_xlfn._xlws.FILTER(ABS('Clutter Trials'!$O$2:$O$42),('Clutter Trials'!$E$2:$E$42<>""))),4)} -> 0.518
A47: Lighting Overall | B47: =B16 -> 382 | C47: =C16 -> 235 | D47: =D16 -> 0.61518325 | E47: =E16 -> 147 | F47: =F16 -> 0.7177 | G47: =G16 -> 0.0093 | H47: =H16 -> 0.0853 | I47: =I16 -> 0.01 | ... K47: =K16 -> 2.107
A48: Baseline Overall | B48: =B25 -> 170 | C48: =C25 -> 127 | D48: =D25 -> 0.74705882 | E48: =E25 -> 43 | F48: =F25 -> 0.6812 | G48: =G25 -> 0.0288 | H48: =H25 -> 0.0613 | I48: =I25 -> 0.011 | ... K48: =K25 -> 1.761
